Traceback (most recent call last):
  File "/cluster/home/lucabri/masterthesis/magging.py", line 140, in <module>
    grouped_dfs[dataset] = pd.DataFrame(list(_Xydata[dataset].groupby(by=grouping_column).apply(fit_and_extract_info, grouping_column, dataset)))
  File "/cluster/home/lucabri/.local/lib/python3.8/site-packages/pandas/core/groupby/groupby.py", line 859, in apply
    result = self._python_apply_general(f, self._selected_obj)
  File "/cluster/home/lucabri/.local/lib/python3.8/site-packages/pandas/core/groupby/groupby.py", line 892, in _python_apply_general
    keys, values, mutated = self.grouper.apply(f, data, self.axis)
  File "/cluster/home/lucabri/.local/lib/python3.8/site-packages/pandas/core/groupby/ops.py", line 220, in apply
    res = f(group)
  File "/cluster/home/lucabri/.local/lib/python3.8/site-packages/pandas/core/groupby/groupby.py", line 843, in f
    return func(g, *args, **kwargs)
  File "/cluster/home/lucabri/masterthesis/magging.py", line 91, in fit_and_extract_info
    search.fit(group_df, group_df['outcome'])
  File "/cluster/home/lucabri/.local/lib/python3.8/site-packages/sklearn/base.py", line 1152, in wrapper
    return fit_method(estimator, *args, **kwargs)
  File "/cluster/home/lucabri/.local/lib/python3.8/site-packages/sklearn/model_selection/_search.py", line 898, in fit
    self._run_search(evaluate_candidates)
  File "/cluster/home/lucabri/.local/lib/python3.8/site-packages/sklearn/model_selection/_search.py", line 1422, in _run_search
    evaluate_candidates(ParameterGrid(self.param_grid))
  File "/cluster/home/lucabri/.local/lib/python3.8/site-packages/sklearn/model_selection/_search.py", line 875, in evaluate_candidates
    _warn_or_raise_about_fit_failures(out, self.error_score)
  File "/cluster/home/lucabri/.local/lib/python3.8/site-packages/sklearn/model_selection/_validation.py", line 414, in _warn_or_raise_about_fit_failures
    raise ValueError(all_fits_failed_message)
ValueError: 
All the 100 fits failed.
It is very likely that your model is misconfigured.
You can try to debug the error by setting error_score='raise'.

Below are more details about the failures:
--------------------------------------------------------------------------------
100 fits failed with the following error:
Traceback (most recent call last):
  File "/cluster/home/lucabri/.local/lib/python3.8/site-packages/pandas/core/indexes/base.py", line 2898, in get_loc
    return self._engine.get_loc(casted_key)
  File "pandas/_libs/index.pyx", line 70, in pandas._libs.index.IndexEngine.get_loc
  File "pandas/_libs/index.pyx", line 101, in pandas._libs.index.IndexEngine.get_loc
  File "pandas/_libs/hashtable_class_helper.pxi", line 1675, in pandas._libs.hashtable.PyObjectHashTable.get_item
  File "pandas/_libs/hashtable_class_helper.pxi", line 1683, in pandas._libs.hashtable.PyObjectHashTable.get_item
KeyError: 'tnt'

The above exception was the direct cause of the following exception:

Traceback (most recent call last):
  File "/cluster/home/lucabri/.local/lib/python3.8/site-packages/sklearn/utils/__init__.py", line 447, in _get_column_indices
    col_idx = all_columns.get_loc(col)
  File "/cluster/home/lucabri/.local/lib/python3.8/site-packages/pandas/core/indexes/base.py", line 2900, in get_loc
    raise KeyError(key) from err
KeyError: 'tnt'

The above exception was the direct cause of the following exception:

Traceback (most recent call last):
  File "/cluster/home/lucabri/.local/lib/python3.8/site-packages/sklearn/model_selection/_validation.py", line 729, in _fit_and_score
    estimator.fit(X_train, y_train, **fit_params)
  File "/cluster/home/lucabri/.local/lib/python3.8/site-packages/sklearn/base.py", line 1152, in wrapper
    return fit_method(estimator, *args, **kwargs)
  File "/cluster/home/lucabri/.local/lib/python3.8/site-packages/sklearn/pipeline.py", line 423, in fit
    Xt = self._fit(X, y, **fit_params_steps)
  File "/cluster/home/lucabri/.local/lib/python3.8/site-packages/sklearn/pipeline.py", line 377, in _fit
    X, fitted_transformer = fit_transform_one_cached(
  File "/cluster/home/lucabri/.local/lib/python3.8/site-packages/joblib/memory.py", line 353, in __call__
    return self.func(*args, **kwargs)
  File "/cluster/home/lucabri/.local/lib/python3.8/site-packages/sklearn/pipeline.py", line 957, in _fit_transform_one
    res = transformer.fit_transform(X, y, **fit_params)
  File "/cluster/home/lucabri/.local/lib/python3.8/site-packages/sklearn/utils/_set_output.py", line 157, in wrapped
    data_to_wrap = f(self, X, *args, **kwargs)
  File "/cluster/home/lucabri/.local/lib/python3.8/site-packages/sklearn/base.py", line 1152, in wrapper
    return fit_method(estimator, *args, **kwargs)
  File "/cluster/home/lucabri/.local/lib/python3.8/site-packages/sklearn/compose/_column_transformer.py", line 751, in fit_transform
    self._validate_column_callables(X)
  File "/cluster/home/lucabri/.local/lib/python3.8/site-packages/sklearn/compose/_column_transformer.py", line 459, in _validate_column_callables
    transformer_to_input_indices[name] = _get_column_indices(X, columns)
  File "/cluster/home/lucabri/.local/lib/python3.8/site-packages/sklearn/utils/__init__.py", line 455, in _get_column_indices
    raise ValueError("A given column is not a column of the dataframe") from e
ValueError: A given column is not a column of the dataframe


real	0m6.642s
user	0m4.922s
sys	0m0.697s
